Workbook

Sheet Hoja1
A1: Codigo | B1: Nombre | C1: Doc.Id. | D1: 1 | E1: 2 | F1: 3 | G1: 4 | H1: 5 | I1: 6 | J1: 7 | K1: 8 | L1: 9 | M1: 10 | N1: 11 | O1: 12 | P1: 13 | Q1: 14 | R1: 15 | S1: 16 | T1: 17 | U1: 18 | V1: 19 | W1: 20 | X1: 21 | Y1: 22 | Z1: 23 | AA1: 24 | AB1: 25 | AC1: 26 | AD1: 27 | AE1: 28 | AF1: 29 | AG1: 30 | AH1: 31 | AI1: 32 | AJ1: MES | AK1: DIAS MES | AL1: TOLERANCIA | AM1: Tard. > 00:10 | AN1: % | AO1: FALTAS | AP1: ESTATUS | AQ1: NOM ABREV
A2: 00001 | B2: CACERES CORDOVA, ROCIO SANDRA | C2: 48429690 | D2: 0.011111111 | E2: 0.0125 | F2: 0.010416667 | G2: 0 | H2: 0.010416667 | I2: F | J2: 0 | K2: 0 | L2: 0.0041666667 | M2: 0 | N2: 0 | O2: 0.015972222 | P2: 0.015277778 | Q2: 0.015277778 | R2: 3:32 | S2: 0.010416667 | T2: 0 | U2: 0 | V2: 0 | W2: 0.015277778 | X2: 0.010416667 | Y2: 0.0069444444 | Z2: 0 | AA2: 0 | AB2: 0 | AC2: F | AD2: 0 | AE2: 0.018055556 | AF2: 0 | AG2: 0 | AH2: 0 | AJ2: 1 | AK2: =COUNTA(D2:AI2) -> 31 | AL2: 0.0069444444 | AM2: =COUNTIF(D2:AI2, ">00:10") -> 11 | AN2: =+AM2/AK2 -> 0.35483871 | AO2: =COUNTIF(D2:AI2,"F") -> 2 | AP2: ACTIVO | AQ2: =CONCATENATE(MID(AU2,1,AV2-1)," ",(MID(AS2,1,AT2-1))) -> ROCIO CACERES | AR2: =SEARCH(",",B2) -> 16 | AS2: =MID(B2,1,AR2-1) -> CACERES CORDOVA | AT2: =SEARCH(" ",AS2) -> 8 | AU2: =MID(B2,AR2+2,90) -> ROCIO SANDRA | AV2: =SEARCH(" ",AU2) -> 6
A3: 00003 | B3: LLANOS YAURI, LOURDES LUCIA | C3: 10602846 | D3: 0 | E3: 0.020833333 | F3: 0.023611111 | G3: 0 | H3: 0.0041666667 | I3: F | J3: 0 | K3: 0.013194444 | L3: 0.025 | M3: 0.0069444444 | N3: 0 | O3: 0.025 | P3: 0.03125 | Q3: 0.01875 | R3: 0.036805556 | S3: 0 | T3: 0 | U3: 0 | V3: 0 | W3: F | X3: F | Y3: F | Z3: F | AA3: F | AB3: 0 | AC3: F | AD3: 0 | AE3: 0.028472222 | AF3: 0 | AG3: 0.0097222222 | AH3: 0.013194444 | AJ3: 1 | AK3: =COUNTA(D3:AI3) -> 31 | AL3: 0.0069444444 | AM3: =COUNTIF(D3:AI3, ">00:10") -> 11 | AN3: =+AM3/AK3 -> 0.35483871 | AO3: =COUNTIF(D3:AI3,"F") -> 7 | AP3: ACTIVO | AQ3: =CONCATENATE(MID(AU3,1,AV3-1)," ",(MID(AS3,1,AT3-1))) -> LOURDES LLANOS | AR3: =SEARCH(",",B3) -> 13 | AS3: =MID(B3,1,AR3-1) -> LLANOS YAURI | AT3: =SEARCH(" ",AS3) -> 7 | AU3: =MID(B3,AR3+2,90) -> LOURDES LUCIA | AV3: =SEARCH(" ",AU3) -> 8
A4: 00004 | B4: TICLLA RAMOS, MARIELLA | C4: 72262268 | D4: F | E4: F | F4: F | G4: 0 | H4: F | I4: F | J4: 0 | K4: F | L4: F | M4: F | N4: 0 | O4: F | P4: F | Q4: F | R4: F | S4: F | T4: 0 | U4: 0 | V4: 0 | W4: F | X4: F | Y4: 0.029166667 | Z4: 0.019444444 | AA4: 0 | AB4: 0 | AC4: 0.015277778 | AD4: 0.014583333 | AE4: 0 | AF4: 0.0097222222 | AG4: 0.010416667 | AH4: 0.0020833333 | AJ4: 1 | AK4: =COUNTA(D4:AI4) -> 31 | AL4: 0.0069444444 | AM4: =COUNTIF(D4:AI4, ">00:10") -> 6 | AN4: =+AM4/AK4 -> 0.19354839 | AO4: =COUNTIF(D4:AI4,"F") -> 15 | AP4: ACTIVO | AQ4: =CONCATENATE(AU4," ",(MID(AS4,1,AT4-1))) -> MARIELLA TICLLA | AR4: =SEARCH(",",B4) -> 13 | AS4: =MID(B4,1,AR4-1) -> TICLLA RAMOS | AT4: =SEARCH(" ",AS4) -> 7 | AU4: =MID(B4,AR4+2,90) -> MARIELLA | AV4: 0
A5: 00006 | B5: PARIONA ROSAS, RICHARD | C5: 71001774 | D5: 0 | E5: F | F5: F | G5: 0 | H5: 0 | I5: F | J5: 0 | K5: 0 | L5: 0.0090277778 | M5: 0.0125 | N5: 0 | O5: 0.0034722222 | P5: 0 | Q5: 0.016666667 | R5: 1:39 | S5: 0.024305556 | T5: 0 | U5: 0 | V5: 0 | W5: 0.0034722222 | X5: 0 | Y5: 0 | Z5: 0 | AA5: 0 | AB5: 0 | AC5: 0 | AD5: 0.013888889 | AE5: 0.0020833333 | AF5: 0.0097222222 | AG5: 0 | AH5: 0.0055555556 | AJ5: 1 | AK5: =COUNTA(D5:AI5) -> 31 | AL5: 0.0069444444 | AM5: =COUNTIF(D5:AI5, ">00:10") -> 6 | AN5: =+AM5/AK5 -> 0.19354839 | AO5: =COUNTIF(D5:AI5,"F") -> 3 | AP5: ACTIVO | AQ5: =CONCATENATE(AU5," ",(MID(AS5,1,AT5-1))) -> RICHARD PARIONA | AR5: =SEARCH(",",B5) -> 14 | AS5: =MID(B5,1,AR5-1) -> PARIONA ROSAS | AT5: =SEARCH(" ",AS5) -> 8 | AU5: =MID(B5,AR5+2,90) -> RICHARD | AV5: =SEARCH(" ",AU5) -> #VALUE!
A6: 00007 | B6: GALINDO MERA, YAHAIRA LUZMILA | C6: 70655433 | D6: 0 | E6: 0.0013888889 | F6: 0.0055555556 | G6: 0 | H6: 0.00069444444 | I6: F | J6: 0 | K6: 0.0055555556 | L6: 0.0090277778 | M6: 0.010416667 | N6: 0 | O6: 0.016666667 | P6: 0.011805556 | Q6: 0.015972222 | R6: 0.029861111 | S6: 0.023611111 | T6: 0 | U6: 0 | V6: 0 | W6: 0.0090277778 | X6: 0.031944444 | Y6: 0.017361111 | Z6: 0 | AA6: 0 | AB6: 0 | AC6: 0 | AD6: 0.014583333 | AE6: 0.010416667 | AF6: 0.0097222222 | AG6: 0 | AH6: 0.0076388889 | AJ6: 1 | AK6: =COUNTA(D6:AI6) -> 31 | AL6: 0.0069444444 | AM6: =COUNTIF(D6:AI6, ">00:10") -> 14 | AN6: =+AM6/AK6 -> 0.4516129 | AO6: =COUNTIF(D6:AI6,"F") -> 1 | AP6: =VLOOKUP(B6,Hoja3!$A$1:$B$14,2,0) -> CESADO | AQ6: =CONCATENATE(MID(AU6,1,AV6-1)," ",(MID(AS6,1,AT6-1))) -> YAHAIRA GALINDO | AR6: =SEARCH(",",B6) -> 13 | AS6: =MID(B6,1,AR6-1) -> GALINDO MERA | AT6: =SEARCH(" ",AS6) -> 8 | AU6: =MID(B6,AR6+2,90) -> YAHAIRA LUZMILA | AV6: =SEARCH(" ",AU6) -> 8
A7: 00008 | B7: LLANOS ANTAURCO, STEPHEN BORIS | C7: 46183969 | D7: 0.014583333 | E7: 0 | F7: 0 | G7: 0 | H7: 0 | I7: F | J7: 0 | K7: 0 | L7: 0.0013888889 | M7: 0 | N7: 0 | O7: 0 | P7: 0 | Q7: 0 | R7: 0.0027777778 | S7: 0.026388889 | T7: 0 | U7: 0 | V7: 0 | W7: 0 | X7: 0 | Y7: 0 | Z7: 0 | AA7: 0 | AB7: 0 | AC7: 0 | AD7: 0 | AE7: 0.0020833333 | AF7: 0.0027777778 | AG7: 0 | AH7: 0 | AJ7: 1 | AK7: =COUNTA(D7:AI7) -> 31 | AL7: 0.0069444444 | AM7: =COUNTIF(D7:AI7, ">00:10") -> 2 | AN7: =+AM7/AK7 -> 0.064516129 | AO7: =COUNTIF(D7:AI7,"F") -> 1 | AP7: ACTIVO | AQ7: =CONCATENATE(MID(AU7,1,AV7-1)," ",(MID(AS7,1,AT7-1))) -> STEPHEN LLANOS | AR7: =SEARCH(",",B7) -> 16 | AS7: =MID(B7,1,AR7-1) -> LLANOS ANTAURCO | AT7: =SEARCH(" ",AS7) -> 7 | AU7: =MID(B7,AR7+2,90) -> STEPHEN BORIS | AV7: =SEARCH(" ",AU7) -> 8
A8: 00010 | B8: CCAMA ARONI, LUZ MIRELLA | C8: 76575233 | D8: 0.01875 | E8: 0.013888889 | F8: 0.010416667 | G8: 0 | H8: 0.0069444444 | I8: F | J8: 0 | K8: 0.0055555556 | L8: 0.0020833333 | M8: 0.0083333333 | N8: 0 | O8: 0.020833333 | P8: 0 | Q8: 0.021527778 | R8: 0.011111111 | S8: 0.010416667 | T8: 0 | U8: 0 | V8: 0 | W8: 0.020833333 | X8: 0.022916667 | Y8: 0.0125 | Z8: 0.0069444444 | AA8: 0 | AB8: 0 | AC8: 0.0013888889 | AD8: 0.021527778 | AE8: 0.017361111 | AF8: 0.034722222 | AG8: 5:03 | AH8: 0.0125 | AJ8: 1 | AK8: =COUNTA(D8:AI8) -> 31 | AL8: 0.0069444444 | AM8: =COUNTIF(D8:AI8, ">00:10") -> 15 | AN8: =+AM8/AK8 -> 0.48387097 | AO8: =COUNTIF(D8:AI8,"F") -> 1 | AP8: ACTIVO | AQ8: =CONCATENATE(MID(AU8,1,AV8-1)," ",(MID(AS8,1,AT8-1))) -> LUZ CCAMA | AR8: =SEARCH(",",B8) -> 12 | AS8: =MID(B8,1,AR8-1) -> CCAMA ARONI | AT8: =SEARCH(" ",AS8) -> 6 | AU8: =MID(B8,AR8+2,90) -> LUZ MIRELLA | AV8: =SEARCH(" ",AU8) -> 4
A9: 00013 | B9: CAYCHO HUANCA, ANDREA ALESSANDRA | C9: 76227067 | D9: 0.0034722222 | E9: 0.0125 | F9: 0.0097222222 | G9: 0 | H9: 0.011805556 | I9: F | J9: 0 | K9: 0 | L9: 0 | M9: 0.022222222 | N9: 0 | O9: 0.015277778 | P9: 0.019444444 | Q9: 0.018055556 | R9: 0.024305556 | S9: 0.022222222 | T9: 0 | U9: 0 | V9: 0 | W9: 0.0097222222 | X9: 0.025 | Y9: 0.026388889 | Z9: 0.022222222 | AA9: 0 | AB9: 0 | AC9: 0 | AD9: 0.011805556 | AE9: 0.023611111 | AF9: 0.013194444 | AG9: 0.0375 | AH9: 0.011805556 | AJ9: 1 | AK9: =COUNTA(D9:AI9) -> 31 | AL9: 0.0069444444 | AM9: =COUNTIF(D9:AI9, ">00:10") -> 18 | AN9: =+AM9/AK9 -> 0.58064516 | AO9: =COUNTIF(D9:AI9,"F") -> 1 | AP9: CESADO | AQ9: =CONCATENATE(MID(AU9,1,AV9-1)," ",(MID(AS9,1,AT9-1))) -> ANDREA CAYCHO | AR9: =SEARCH(",",B9) -> 14 | AS9: =MID(B9,1,AR9-1) -> CAYCHO HUANCA | AT9: =SEARCH(" ",AS9) -> 7 | AU9: =MID(B9,AR9+2,90) -> ANDREA ALESSANDRA | AV9: =SEARCH(" ",AU9) -> 7
A10: 00014 | B10: PAREDES GUILLEN, ROCIO NOEMI | C10: 09930677 | D10: 0 | E10: 0 | F10: 0 | G10: 0 | H10: 0 | I10: F | J10: 0 | K10: 0 | L10: 0 | M10: 0 | N10: 0 | O10: 0 | P10: 0 | Q10: 0 | R10: 0 | S10: 0 | T10: 0 | U10: 0 | V10: 0 | W10: 0 | X10: 0 | Y10: 1:11 | Z10: 0 | AA10: 0 | AB10: 0 | AC10: 0 | AD10: 0 | AE10: 0 | AF10: 0.0097222222 | AG10: 0 | AH10: 0.020833333 | AJ10: 1 | AK10: =COUNTA(D10:AI10) -> 31 | AL10: 0.0069444444 | AM10: =COUNTIF(D10:AI10, ">00:10") -> 2 | AN10: =+AM10/AK10 -> 0.064516129 | AO10: =COUNTIF(D10:AI10,"F") -> 1 | AP10: =VLOOKUP(B10,Hoja3!$A$1:$B$14,2,0) -> CESADO | AQ10: =CONCATENATE(MID(AU10,1,AV10-1)," ",(MID(AS10,1,AT10-1))) -> ROCIO PAREDES | AR10: =SEARCH(",",B10) -> 16 | AS10: =MID(B10,1,AR10-1) -> PAREDES GUILLEN | AT10: =SEARCH(" ",AS10) -> 8 | AU10: =MID(B10,AR10+2,90) -> ROCIO NOEMI | AV10: =SEARCH(" ",AU10) -> 6
A11: 00016 | B11: GUEVARA ENRIQUEZ, ROGELIO | C11: 70237404 | D11: 0 | E11: 0 | F11: 0 | G11: 0 | H11: 0 | I11: F | J11: 0 | K11: 0 | L11: 0 | M11: 0.0013888889 | N11: 0 | O11: 0 | P11: 0 | Q11: 0 | R11: 0 | S11: 0 | T11: 0 | U11: 0 | V11: 0 | W11: 0 | X11: 0 | Y11: 0 | Z11: 0 | AA11: 0 | AB11: 0 | AC11: 0 | AD11: 0 | AE11: 0 | AF11: 0 | AG11: 0 | AH11: 0 | AJ11: 1 | AK11: =COUNTA(D11:AI11) -> 31 | AL11: 0.0069444444 | AM11: =COUNTIF(D11:AI11, ">00:10") -> 0 | AN11: =+AM11/AK11 -> 0 | AO11: =COUNTIF(D11:AI11,"F") -> 1 | AP11: =VLOOKUP(B11,Hoja3!$A$1:$B$14,2,0) -> CESADO | AQ11: =CONCATENATE(AU11," ",(MID(AS11,1,AT11-1))) -> ROGELIO GUEVARA | AR11: =SEARCH(",",B11) -> 17 | AS11: =MID(B11,1,AR11-1) -> GUEVARA ENRIQUEZ | AT11: =SEARCH(" ",AS11) -> 8 | AU11: =MID(B11,AR11+2,90) -> ROGELIO | AV11: =SEARCH(" ",AU11) -> #VALUE!
A12: 00017 | B12: ASIAN RAMIREZ, SILVIA LARITZA | C12: 70098369 | D12: 0.0125 | E12: 1:00 | F12: 0.015277778 | G12: 0 | H12: 0 | I12: F | J12: 0 | K12: 0.027083333 | L12: 0 | M12: 0.0055555556 | N12: 0 | O12: 0.016666667 | P12: 0.0069444444 | Q12: 0.017361111 | R12: 0.033333333 | S12: 0 | T12: 0 | U12: 0 | V12: 0 | W12: 0 | X12: 0.017361111 | Y12: 0.020833333 | Z12: 0.013194444 | AA12: F | AB12: 0 | AC12: 0.029861111 | AD12: 0.032638889 | AE12: 0 | AF12: 0 | AG12: 0.011111111 | AH12: 0.0048611111 | AJ12: 1 | AK12: =COUNTA(D12:AI12) -> 31 | AL12: 0.0069444444 | AM12: =COUNTIF(D12:AI12, ">00:10") -> 12 | AN12: =+AM12/AK12 -> 0.38709677 | AO12: =COUNTIF(D12:AI12,"F") -> 2 | AP12: =VLOOKUP(B12,Hoja3!$A$1:$B$14,2,0) -> CESADO | AQ12: =CONCATENATE(MID(AU12,1,AV12-1)," ",(MID(AS12,1,AT12-1))) -> SILVIA ASIAN | AR12: =SEARCH(",",B12) -> 14 | AS12: =MID(B12,1,AR12-1) -> ASIAN RAMIREZ | AT12: =SEARCH(" ",AS12) -> 6 | AU12: =MID(B12,AR12+2,90) -> SILVIA LARITZA | AV12: =SEARCH(" ",AU12) -> 7
A13: 00021 | B13: PRETELL PINTADO, ANGELICA DIANA | C13: 72648191 | D13: 0.015972222 | E13: 0.020833333 | F13: 1:02 | G13: 0 | H13: 0.029166667 | I13: F | J13: 0 | K13: 0.023611111 | L13: 0.010416667 | M13: 0.011111111 | N13: 0 | O13: 0.025694444 | P13: 0.030555556 | Q13: 0.013888889 | R13: 0.03125 | S13: 0.017361111 | T13: 0 | U13: 0 | V13: 0 | W13: 0.020833333 | X13: 0.014583333 | Y13: 0.018055556 | Z13: 0 | AA13: 0 | AB13: 0 | AC13: 0 | AD13: 0.0069444444 | AE13: 0.030555556 | AF13: 0.027777778 | AG13: 0.027777778 | AH13: 0.0125 | AJ13: 1 | AK13: =COUNTA(D13:AI13) -> 31 | AL13: 0.0069444444 | AM13: =COUNTIF(D13:AI13, ">00:10") -> 18 | AN13: =+AM13/AK13 -> 0.58064516 | AO13: =COUNTIF(D13:AI13,"F") -> 1 | AP13: CESADO | AQ13: =CONCATENATE(MID(AU13,1,AV13-1)," ",(MID(AS13,1,AT13-1))) -> ANGELICA PRETELL | AR13: =SEARCH(",",B13) -> 16 | AS13: =MID(B13,1,AR13-1) -> PRETELL PINTADO | AT13: =SEARCH(" ",AS13) -> 8 | AU13: =MID(B13,AR13+2,90) -> ANGELICA DIANA | AV13: =SEARCH(" ",AU13) -> 9
A14: 00022 | B14: TENORIO FELIX, SAMANTHA NICOLLE | C14: 72925189 | D14: F | E14: 0 | F14: 0.015277778 | G14: 0 | H14: 0 | I14: F | J14: 0 | K14: 0 | L14: 0 | M14: 0.010416667 | N14: 0 | O14: 0 | P14: 0.014583333 | Q14: 0 | R14: 0.013888889 | S14: 0 | T14: 0 | U14: 0 | V14: 0 | W14: 0 | X14: 0.020138889 | Y14: 0 | Z14: 0.013194444 | AA14: 0 | AB14: 0 | AC14: F | AD14: F | AE14: F | AF14: F | AG14: 0.039583333 | AH14: 1:15 | AJ14: 1 | AK14: =COUNTA(D14:AI14) -> 31 | AL14: 0.0069444444 | AM14: =COUNTIF(D14:AI14, ">00:10") -> 7 | AN14: =+AM14/AK14 -> 0.22580645 | AO14: =COUNTIF(D14:AI14,"F") -> 6 | AP14: =VLOOKUP(B14,Hoja3!$A$1:$B$14,2,0) -> CESADO | AQ14: =CONCATENATE(MID(AU14,1,AV14-1)," ",(MID(AS14,1,AT14-1))) -> SAMANTHA TENORIO | AR14: =SEARCH(",",B14) -> 14 | AS14: =MID(B14,1,AR14-1) -> TENORIO FELIX | AT14: =SEARCH(" ",AS14) -> 8 | AU14: =MID(B14,AR14+2,90) -> SAMANTHA NICOLLE | AV14: =SEARCH(" ",AU14) -> 9
A15: 00023 | B15: LOPEZ FARIAS, CARLOS JOAQUIN | C15: 73619936 | D15: 0.0041666667 | E15: 0.0034722222 | F15: 0 | G15: 0 | H15: 0.00625 | I15: F | J15: 0 | K15: F | L15: 0 | M15: 0.010416667 | N15: 0 | O15: 0.00069444444 | P15: 0 | Q15: 0 | R15: 0.029861111 | S15: 0 | T15: 0 | U15: 0 | V15: 0 | W15: 0.011111111 | X15: 0.00069444444 | Y15: 0.0083333333 | Z15: 0.0069444444 | AA15: 0 | AB15: 0 | AC15: 0 | AD15: 0 | AE15: 0.0055555556 | AF15: 0 | AG15: 0.0027777778 | AH15: 0.015277778 | AJ15: 1 | AK15: =COUNTA(D15:AI15) -> 31 | AL15: 0.0069444444 | AM15: =COUNTIF(D15:AI15, ">00:10") -> 5 | AN15: =+AM15/AK15 -> 0.16129032 | AO15: =COUNTIF(D15:AI15,"F") -> 2 | AP15: ACTIVO | AQ15: =CONCATENATE(MID(AU15,1,AV15-1)," ",(MID(AS15,1,AT15-1))) -> CARLOS LOPEZ | AR15: =SEARCH(",",B15) -> 13 | AS15: =MID(B15,1,AR15-1) -> LOPEZ FARIAS | AT15: =SEARCH(" ",AS15) -> 6 | AU15: =MID(B15,AR15+2,90) -> CARLOS JOAQUIN | AV15: =SEARCH(" ",AU15) -> 7
A16: 00024 | B16: LOPEZ CRUZ, JEFFERSON NORMAN | C16: 72754919 | D16: 0.0048611111 | E16: 0 | F16: 0 | G16: 0 | H16: 0.0020833333 | I16: F | J16: 0 | K16: 0.0027777778 | L16: 0.0083333333 | M16: 0 | N16: 0 | O16: 2:47 | P16: 0.029166667 | Q16: 0 | R16: 0.024305556 | S16: 0.0090277778 | T16: 0 | U16: 0 | V16: 0 | W16: 0.014583333 | X16: 0.0125 | Y16: 0.015972222 | Z16: 0.0055555556 | AA16: 0 | AB16: 0 | AC16: 0 | AD16: 0.0027777778 | AE16: 0 | AF16: 0.014583333 | AG16: 0.038888889 | AH16: 0.023611111 | AJ16: 1 | AK16: =COUNTA(D16:AI16) -> 31 | AL16: 0.0069444444 | AM16: =COUNTIF(D16:AI16, ">00:10") -> 10 | AN16: =+AM16/AK16 -> 0.32258065 | AO16: =COUNTIF(D16:AI16,"F") -> 1 | AP16: =VLOOKUP(B16,Hoja3!$A$1:$B$14,2,0) -> CESADO | AQ16: =CONCATENATE(MID(AU16,1,AV16-1)," ",(MID(AS16,1,AT16-1))) -> JEFFERSON LOPEZ | AR16: =SEARCH(",",B16) -> 11 | AS16: =MID(B16,1,AR16-1) -> LOPEZ CRUZ | AT16: =SEARCH(" ",AS16) -> 6 | AU16: =MID(B16,AR16+2,90) -> JEFFERSON NORMAN | AV16: =SEARCH(" ",AU16) -> 10
A17: 00025 | B17: CRUZ TAIPE, RONY WALDIR | C17: 76848378 | D17: 0.0090277778 | E17: 0 | F17: 0 | G17: 0 | H17: 0.0055555556 | I17: 5:11 | J17: 0 | K17: 0 | L17: 0 | M17: 1:18 | N17: 0 | O17: 0.0027777778 | P17: 0.033333333 | Q17: 0 | R17: 0.0083333333 | S17: 0.0055555556 | T17: 0 | U17: 0 | V17: 0 | W17: 0 | X17: 0 | Y17: 0 | Z17: 0 | AA17: 0.0027777778 | AB17: 0 | AC17: 0 | AD17: 4:43 | AE17: 0 | AF17: 0 | AG17: 0 | AH17: 0 | AJ17: 1 | AK17: =COUNTA(D17:AI17) -> 31 | AL17: 0.0069444444 | AM17: =COUNTIF(D17:AI17, ">00:10") -> 3 | AN17: =+AM17/AK17 -> 0.096774194 | AO17: =COUNTIF(D17:AI17,"F") -> 0 | AP17: ACTIVO | AQ17: =CONCATENATE(MID(AU17,1,AV17-1)," ",(MID(AS17,1,AT17-1))) -> RONY CRUZ | AR17: =SEARCH(",",B17) -> 11 | AS17: =MID(B17,1,AR17-1) -> CRUZ TAIPE | AT17: =SEARCH(" ",AS17) -> 5 | AU17: =MID(B17,AR17+2,90) -> RONY WALDIR | AV17: =SEARCH(" ",AU17) -> 5
A18: 00026 | B18: ANDRADE MERA, MARQUIÑO ANTONY | C18: 74768155 | D18: 0.0041666667 | E18: 0.011111111 | F18: 0.0090277778 | G18: 0 | H18: 0 | I18: F | J18: 0 | K18: F | L18: 0 | M18: 0 | N18: 0 | O18: 0.0375 | P18: 0 | Q18: 0 | R18: 0.0020833333 | S18: 0.019444444 | T18: 0 | U18: 0 | V18: 0 | W18: 0.0076388889 | X18: 0.010416667 | Y18: 0.014583333 | Z18: 0.010416667 | AA18: 0 | AB18: 0 | AC18: 0 | AD18: 0.0090277778 | AE18: 0 | AF18: 0 | AG18: 0.017361111 | AH18: 0.0041666667 | AJ18: 1 | AK18: =COUNTA(D18:AI18) -> 31 | AL18: 0.0069444444 | AM18: =COUNTIF(D18:AI18, ">00:10") -> 10 | AN18: =+AM18/AK18 -> 0.32258065 | AO18: =COUNTIF(D18:AI18,"F") -> 2 | AP18: CESADO | AQ18: =CONCATENATE(MID(AU18,1,AV18-1)," ",(MID(AS18,1,AT18-1))) -> MARQUIÑO ANDRADE | AR18: =SEARCH(",",B18) -> 13 | AS18: =MID(B18,1,AR18-1) -> ANDRADE MERA | AT18: =SEARCH(" ",AS18) -> 8 | AU18: =MID(B18,AR18+2,90) -> MARQUIÑO ANTONY | AV18: =SEARCH(" ",AU18) -> 9
A19: 00027 | B19: FELIX GARCIA, JEAN PIERRE | C19: 73453354 | D19: 0.011111111 | E19: 1:09 | F19: 0.0055555556 | G19: 0 | H19: 0.017361111 | I19: F | J19: 0 | K19: 0.031944444 | L19: F | M19: 0.039583333 | N19: 0 | O19: 0 | P19: 1:07 | Q19: 0.036111111 | R19: 0 | S19: 0.020138889 | T19: 0 | U19: 0 | V19: 0 | W19: 0.029166667 | X19: 0.0034722222 | Y19: 0 | Z19: 0.020138889 | AA19: 0 | AB19: 0 | AC19: 0 | AD19: 0 | AE19: 0 | AF19: 0 | AG19: 0 | AH19: 0 | AJ19: 1 | AK19: =COUNTA(D19:AI19) -> 31 | AL19: 0.0069444444 | AM19: =COUNTIF(D19:AI19, ">00:10") -> 8 | AN19: =+AM19/AK19 -> 0.25806452 | AO19: =COUNTIF(D19:AI19,"F") -> 2 | AP19: =VLOOKUP(B19,Hoja3!$A$1:$B$14,2,0) -> CESADO | AQ19: =CONCATENATE(MID(AU19,1,AV19-1)," ",(MID(AS19,1,AT19-1))) -> JEAN FELIX | AR19: =SEARCH(",",B19) -> 13 | AS19: =MID(B19,1,AR19-1) -> FELIX GARCIA | AT19: =SEARCH(" ",AS19) -> 6 | AU19: =MID(B19,AR19+2,90) -> JEAN PIERRE | AV19: =SEARCH(" ",AU19) -> 5
A20: 00028 | B20: CLAROS NIETO, LITTA DANERY | C20: 47329796 | D20: 0.035416667 | E20: 1:03 | F20: 0 | G20: 0 | H20: 0.0055555556 | I20: F | J20: 0 | K20: 0.034027778 | L20: 1:18 | M20: 0.0041666667 | N20: 0 | O20: 0.015277778 | P20: 0.022222222 | Q20: 0.013194444 | R20: 0.032638889 | S20: 0.022916667 | T20: 0 | U20: 0 | V20: 0 | W20: 0.0048611111 | X20: 0.022916667 | Y20: 0.028472222 | Z20: 0 | AA20: 0 | AB20: 0 | AC20: F | AD20: 0.027777778 | AE20: 0.0083333333 | AF20: 0.031944444 | AG20: 0 | AH20: 0.010416667 | AJ20: 1 | AK20: =COUNTA(D20:AI20) -> 31 | AL20: 0.0069444444 | AM20: =COUNTIF(D20:AI20, ">00:10") -> 13 | AN20: =+AM20/AK20 -> 0.41935484 | AO20: =COUNTIF(D20:AI20,"F") -> 2 | AP20: =VLOOKUP(B20,Hoja3!$A$1:$B$14,2,0) -> CESADO | AQ20: =CONCATENATE(MID(AU20,1,AV20-1)," ",(MID(AS20,1,AT20-1))) -> LITTA CLAROS | AR20: =SEARCH(",",B20) -> 13 | AS20: =MID(B20,1,AR20-1) -> CLAROS NIETO | AT20: =SEARCH(" ",AS20) -> 7 | AU20: =MID(B20,AR20+2,90) -> LITTA DANERY | AV20: =SEARCH(" ",AU20) -> 6
A21: 00029 | B21: CCARI ASILLO, JHON MILTHON | C21: 77822746 | D21: 0 | E21: 0.038888889 | F21: 0.036111111 | G21: 0 | H21: 0 | I21: 0 | J21: 0 | K21: 0 | L21: 0 | M21: 0 | N21: 0 | O21: 0 | P21: 0 | Q21: 0 | R21: 0 | S21: 0 | T21: 0 | U21: 0 | V21: 0 | W21: 0 | X21: 0 | Y21: 0 | Z21: 0 | AA21: 0 | AB21: 0 | AC21: 0 | AD21: 0 | AE21: 0 | AF21: 0 | AG21: 0 | AH21: 0 | AJ21: 1 | AK21: =COUNTA(D21:AI21) -> 31 | AL21: 0.0069444444 | AM21: =COUNTIF(D21:AI21, ">00:10") -> 2 | AN21: =+AM21/AK21 -> 0.064516129 | AO21: =COUNTIF(D21:AI21,"F") -> 0 | AP21: =VLOOKUP(B21,Hoja3!$A$1:$B$14,2,0) -> CESADO | AQ21: =CONCATENATE(MID(AU21,1,AV21-1)," ",(MID(AS21,1,AT21-1))) -> JHON CCARI | AR21: =SEARCH(",",B21) -> 13 | AS21: =MID(B21,1,AR21-1) -> CCARI ASILLO | AT21: =SEARCH(" ",AS21) -> 6 | AU21: =MID(B21,AR21+2,90) -> JHON MILTHON | AV21: =SEARCH(" ",AU21) -> 5
A22: 00034 | B22: MEJIA TORRES, FRANCISCO JAVIER | C22: 72350882 | D22: 0 | E22: 0 | F22: 0 | G22: 0 | H22: 0 | I22: F | J22: 0 | K22: 0 | L22: 0.0020833333 | M22: 0 | N22: 0 | O22: 0.0041666667 | P22: 0 | Q22: 0.0048611111 | R22: 0.0013888889 | S22: 0.0013888889 | T22: 0 | U22: 0 | V22: 0 | W22: 0.0034722222 | X22: 0 | Y22: 0 | Z22: 0 | AA22: 0 | AB22: 0 | AC22: 0.0076388889 | AD22: 0 | AE22: 0.00069444444 | AF22: 0 | AG22: 0.0027777778 | AH22: 0 | AJ22: 1 | AK22: =COUNTA(D22:AI22) -> 31 | AL22: 0.0069444444 | AM22: =COUNTIF(D22:AI22, ">00:10") -> 1 | AN22: =+AM22/AK22 -> 0.032258065 | AO22: =COUNTIF(D22:AI22,"F") -> 1 | AP22: ACTIVO | AQ22: =CONCATENATE(MID(AU22,1,AV22-1)," ",(MID(AS22,1,AT22-1))) -> FRANCISCO MEJIA | AR22: =SEARCH(",",B22) -> 13 | AS22: =MID(B22,1,AR22-1) -> MEJIA TORRES | AT22: =SEARCH(" ",AS22) -> 6 | AU22: =MID(B22,AR22+2,90) -> FRANCISCO JAVIER | AV22: =SEARCH(" ",AU22) -> 10
A23: 00035 | B23: GUEVARA CABELLO, CARLOS JEANPIERRE | C23: 74026944 | D23: 0.0013888889 | E23: 0.0020833333 | F23: 0 | G23: 0 | H23: 0 | I23: F | J23: 0 | K23: 0 | L23: 0.0041666667 | M23: 0 | N23: 0 | O23: 0 | P23: 0.0034722222 | Q23: 0.0034722222 | R23: 0 | S23: 0 | T23: 0 | U23: 0 | V23: 0 | W23: 0 | X23: 0.00069444444 | Y23: 0.0027777778 | Z23: 0.0083333333 | AA23: 0 | AB23: 0 | AC23: 0.00625 | AD23: 0.0076388889 | AE23: 0 | AF23: 0 | AG23: 0.0034722222 | AH23: 0 | AJ23: 1 | AK23: =COUNTA(D23:AI23) -> 31 | AL23: 0.0069444444 | AM23: =COUNTIF(D23:AI23, ">00:10") -> 2 | AN23: =+AM23/AK23 -> 0.064516129 | AO23: =COUNTIF(D23:AI23,"F") -> 1 | AP23: ACTIVO | AQ23: =CONCATENATE(MID(AU23,1,AV23-1)," ",(MID(AS23,1,AT23-1))) -> CARLOS GUEVARA | AR23: =SEARCH(",",B23) -> 16 | AS23: =MID(B23,1,AR23-1) -> GUEVARA CABELLO | AT23: =SEARCH(" ",AS23) -> 8 | AU23: =MID(B23,AR23+2,90) -> CARLOS JEANPIERRE | AV23: =SEARCH(" ",AU23) -> 7
A24: 00036 | B24: AMES ESPINOZA, KIMBERLLY | C24: 75149675 | D24: 0 | E24: 0.010416667 | F24: 0 | G24: 0 | H24: 0 | I24: F | J24: 0 | K24: 0 | L24: 0 | M24: 0.0013888889 | N24: 0 | O24: 0 | P24: 0.00625 | Q24: 0.014583333 | R24: 0.0125 | S24: 0 | T24: 0 | U24: 0 | V24: 0 | W24: 0.0125 | X24: 0 | Y24: 0 | Z24: 0.011111111 | AA24: 0 | AB24: 0 | AC24: 0.0048611111 | AD24: 0 | AE24: 0 | AF24: 0 | AG24: 0.026388889 | AH24: F | AJ24: 1 | AK24: =COUNTA(D24:AI24) -> 31 | AL24: 0.0069444444 | AM24: =COUNTIF(D24:AI24, ">00:10") -> 6 | AN24: =+AM24/AK24 -> 0.19354839 | AO24: =COUNTIF(D24:AI24,"F") -> 2 | AP24: ACTIVO | AQ24: =CONCATENATE(AU24," ",(MID(AS24,1,AT24-1))) -> KIMBERLLY AMES | AR24: =SEARCH(",",B24) -> 14 | AS24: =MID(B24,1,AR24-1) -> AMES ESPINOZA | AT24: =SEARCH(" ",AS24) -> 5 | AU24: =MID(B24,AR24+2,90) -> KIMBERLLY | AV24: =SEARCH(" ",AU24) -> #VALUE!
A25: 00037 | B25: ALVARADO ECHAIZ, LILIANA | C25: 15739413 | D25: 0.0076388889 | E25: 0 | F25: 0.0055555556 | G25: 0 | H25: 0.00625 | I25: F | J25: 0 | K25: 0.0055555556 | L25: 0.0041666667 | M25: 0.0083333333 | N25: 0 | O25: 0.0083333333 | P25: 0.0125 | Q25: 0.0097222222 | R25: 0.0083333333 | S25: 0 | T25: 0 | U25: 0 | V25: 0 | W25: 0.013194444 | X25: 0.015972222 | Y25: 0.011805556 | Z25: 0 | AA25: 0 | AB25: 0 | AC25: 0.0048611111 | AD25: 0.013888889 | AE25: 0.0083333333 | AF25: 0.018055556 | AG25: 0 | AH25: 0.011111111 | AJ25: 1 | AK25: =COUNTA(D25:AI25) -> 31 | AL25: 0.0069444444 | AM25: =COUNTIF(D25:AI25, ">00:10") -> 13 | AN25: =+AM25/AK25 -> 0.41935484 | AO25: =COUNTIF(D25:AI25,"F") -> 1 | AP25: ACTIVO | AQ25: =CONCATENATE(AU25," ",(MID(AS25,1,AT25-1))) -> LILIANA ALVARADO | AR25: =SEARCH(",",B25) -> 16 | AS25: =MID(B25,1,AR25-1) -> ALVARADO ECHAIZ | AT25: =SEARCH(" ",AS25) -> 9 | AU25: =MID(B25,AR25+2,90) -> LILIANA | AV25: =SEARCH(" ",AU25) -> #VALUE!
A26: 00038 | B26: MAYTA HUANCA, LUZ GABY | C26: 73655629 | D26: F | E26: F | F26: F | G26: 0 | H26: F | I26: F | J26: 0 | K26: F | L26: F | M26: F | N26: 0 | O26: 0 | P26: 0 | Q26: 0 | R26: 0 | S26: 0 | T26: 0 | U26: 0 | V26: 0 | W26: 0 | X26: 0 | Y26: 0 | Z26: 0 | AA26: 0 | AB26: 0 | AC26: 0 | AD26: 0 | AE26: 0 | AF26: 0 | AG26: 0 | AH26: 0 | AJ26: 1 | AK26: =COUNTA(D26:AI26) -> 31 | AL26: 0.0069444444 | AM26: =COUNTIF(D26:AI26, ">00:10") -> 0 | AN26: =+AM26/AK26 -> 0 | AO26: =COUNTIF(D26:AI26,"F") -> 8 | AP26: =VLOOKUP(B26,Hoja3!$A$1:$B$14,2,0) -> CESADO | AQ26: =CONCATENATE(MID(AU26,1,AV26-1)," ",(MID(AS26,1,AT26-1))) -> LUZ MAYTA | AR26: =SEARCH(",",B26) -> 13 | AS26: =MID(B26,1,AR26-1) -> MAYTA HUANCA | AT26: =SEARCH(" ",AS26) -> 6 | AU26: =MID(B26,AR26+2,90) -> LUZ GABY | AV26: =SEARCH(" ",AU26) -> 4
A27: 00039 | B27: ALVAREZ MINAYA, BRIGHITTE SONIA | C27: 74071396 | D27: 0.011805556 | E27: 0.011111111 | F27: 0 | G27: 0 | H27: 0.0020833333 | I27: F | J27: 0 | K27: 0.0097222222 | L27: 0.033333333 | M27: F | N27: 0 | O27: 0 | P27: 0 | Q27: 0 | R27: 0 | S27: 0 | T27: 0 | U27: 0 | V27: 0 | W27: 0 | X27: 0 | Y27: 0 | Z27: 0 | AA27: 0 | AB27: 0 | AC27: 0 | AD27: 0 | AE27: 0 | AF27: 0 | AG27: 0 | AH27: 0 | AJ27: 1 | AK27: =COUNTA(D27:AI27) -> 31 | AL27: 0.0069444444 | AM27: =COUNTIF(D27:AI27, ">00:10") -> 4 | AN27: =+AM27/AK27 -> 0.12903226 | AO27: =COUNTIF(D27:AI27,"F") -> 2 | AP27: CESADO | AQ27: =CONCATENATE(MID(AU27,1,AV27-1)," ",(MID(AS27,1,AT27-1))) -> BRIGHITTE ALVAREZ | AR27: =SEARCH(",",B27) -> 15 | AS27: =MID(B27,1,AR27-1) -> ALVAREZ MINAYA | AT27: =SEARCH(" ",AS27) -> 8 | AU27: =MID(B27,AR27+2,90) -> BRIGHITTE SONIA | AV27: =SEARCH(" ",AU27) -> 10
A28: 00040 | B28: MERMA CHILA, MANUEL ENRIQUE | C28: 75925906 | D28: 0 | E28: 0 | F28: 0 | G28: 0 | H28: 0 | I28: 0 | J28: 0 | K28: 5:04 | L28: 0 | M28: 0 | N28: 0 | O28: 0.0013888889 | P28: 0 | Q28: 0.00069444444 | R28: 0 | S28: 0 | T28: 0 | U28: 0 | V28: 0 | W28: 0 | X28: 0 | Y28: 0.00625 | Z28: 0 | AA28: 0 | AB28: 0 | AC28: 0 | AD28: 0.00625 | AE28: 0 | AF28: 0 | AG28: 0 | AH28: 0 | AJ28: 1 | AK28: =COUNTA(D28:AI28) -> 31 | AL28: 0.0069444444 | AM28: =COUNTIF(D28:AI28, ">00:10") -> 0 | AN28: =+AM28/AK28 -> 0 | AO28: =COUNTIF(D28:AI28,"F") -> 0 | AP28: ACTIVO | AQ28: =CONCATENATE(MID(AU28,1,AV28-1)," ",(MID(AS28,1,AT28-1))) -> MANUEL MERMA | AR28: =SEARCH(",",B28) -> 12 | AS28: =MID(B28,1,AR28-1) -> MERMA CHILA | AT28: =SEARCH(" ",AS28) -> 6 | AU28: =MID(B28,AR28+2,90) -> MANUEL ENRIQUE | AV28: =SEARCH(" ",AU28) -> 7
A29: 00041 | B29: SANCHEZ PANAIFO, GRECIA DANNAE | C29: 48420673 | D29: 0 | E29: 0 | F29: 0 | G29: 0 | H29: 0 | I29: 0 | J29: 0 | K29: 0 | L29: 0 | M29: 0 | N29: 0 | O29: 0 | P29: 0 | Q29: 0 | R29: F | S29: F | T29: 0 | U29: 0 | V29: 0 | W29: F | X29: F | Y29: F | Z29: F | AA29: F | AB29: 0 | AC29: F | AD29: F | AE29: 0 | AF29: 0 | AG29: 0.0041666667 | AH29: 0.0097222222 | AJ29: 1 | AK29: =COUNTA(D29:AI29) -> 31 | AL29: 0.0069444444 | AM29: =COUNTIF(D29:AI29, ">00:10") -> 1 | AN29: =+AM29/AK29 -> 0.032258065 | AO29: =COUNTIF(D29:AI29,"F") -> 9 | AP29: ACTIVO | AQ29: =CONCATENATE(MID(AU29,1,AV29-1)," ",(MID(AS29,1,AT29-1))) -> GRECIA SANCHEZ | AR29: =SEARCH(",",B29) -> 16 | AS29: =MID(B29,1,AR29-1) -> SANCHEZ PANAIFO | AT29: =SEARCH(" ",AS29) -> 8 | AU29: =MID(B29,AR29+2,90) -> GRECIA DANNAE | AV29: =SEARCH(" ",AU29) -> 7
A30: 00042 | B30: CHAVEZ GUILLEN, DIANA CAROLINA | C30: 71007128 | D30: 0 | E30: 0 | F30: 0 | G30: 0 | H30: 0 | I30: 0 | J30: 0 | K30: 0 | L30: 0 | M30: 0 | N30: 0 | O30: 0 | P30: 0 | Q30: 0 | R30: 0 | S30: 4:07 | T30: 0 | U30: 0 | V30: 0 | W30: 0 | X30: 0 | Y30: 0 | Z30: 0 | AA30: 0 | AB30: 0 | AC30: 0 | AD30: 0 | AE30: 0 | AF30: 0.0013888889 | AG30: 0 | AH30: 0.00069444444 | AJ30: 1 | AK30: =COUNTA(D30:AI30) -> 31 | AL30: 0.0069444444 | AM30: =COUNTIF(D30:AI30, ">00:10") -> 0 | AN30: =+AM30/AK30 -> 0 | AO30: =COUNTIF(D30:AI30,"F") -> 0 | AP30: =VLOOKUP(B30,Hoja3!$A$1:$B$14,2,0) -> CESADO | AQ30: =CONCATENATE(MID(AU30,1,AV30-1)," ",(MID(AS30,1,AT30-1))) -> DIANA CHAVEZ | AR30: =SEARCH(",",B30) -> 15 | AS30: =MID(B30,1,AR30-1) -> CHAVEZ GUILLEN | AT30: =SEARCH(" ",AS30) -> 7 | AU30: =MID(B30,AR30+2,90) -> DIANA CAROLINA | AV30: =SEARCH(" ",AU30) -> 6
A31: 00043 | B31: URDAY CHOQUE, JONATHAN EDGARD | C31: 71432329 | D31: 0 | E31: 0 | F31: 0 | G31: 0 | H31: 0 | I31: 0 | J31: 0 | K31: 0 | L31: 0 | M31: 0 | N31: 0 | O31: 0 | P31: 0 | Q31: 0 | R31: 0 | S31: 0 | T31: 0 | U31: 0 | V31: 0 | W31: 0 | X31: 0 | Y31: 0 | Z31: 0 | AA31: 0 | AB31: 0 | AC31: 0 | AD31: 0 | AE31: 0 | AF31: 0 | AG31: 0 | AH31: 0.00069444444 | AJ31: 1 | AK31: =COUNTA(D31:AI31) -> 31 | AL31: 0.0069444444 | AM31: =COUNTIF(D31:AI31, ">00:10") -> 0 | AN31: =+AM31/AK31 -> 0 | AO31: =COUNTIF(D31:AI31,"F") -> 0 | AP31: ACTIVO | AQ31: =CONCATENATE(MID(AU31,1,AV31-1)," ",(MID(AS31,1,AT31-1))) -> JONATHAN URDAY | AR31: =SEARCH(",",B31) -> 13 | AS31: =MID(B31,1,AR31-1) -> URDAY CHOQUE | AT31: =SEARCH(" ",AS31) -> 6 | AU31: =MID(B31,AR31+2,90) -> JONATHAN EDGARD | AV31: =SEARCH(" ",AU31) -> 9
A32: 00044 | B32: PEREZ VERA, MARLENE BETTY | C32: 72092638 | D32: 0 | E32: 0 | F32: 0 | G32: 0 | H32: 0 | I32: 0 | J32: 0 | K32: 0 | L32: 0 | M32: 0 | N32: 0 | O32: 0 | P32: 0 | Q32: 0 | R32: 0 | S32: 4:07 | T32: 0 | U32: 0 | V32: 0 | W32: 0 | X32: 0 | Y32: 0 | Z32: 0 | AA32: 0 | AB32: 0 | AC32: 0 | AD32: 0 | AE32: 0 | AF32: 0 | AG32: 0 | AH32: 0 | AJ32: 1 | AK32: =COUNTA(D32:AI32) -> 31 | AL32: 0.0069444444 | AM32: =COUNTIF(D32:AI32, ">00:10") -> 0 | AN32: =+AM32/AK32 -> 0 | AO32: =COUNTIF(D32:AI32,"F") -> 0 | AP32: =VLOOKUP(B32,Hoja3!$A$1:$B$14,2,0) -> CESADO | AQ32: =CONCATENATE(MID(AU32,1,AV32-1)," ",(MID(AS32,1,AT32-1))) -> MARLENE PEREZ | AR32: =SEARCH(",",B32) -> 11 | AS32: =MID(B32,1,AR32-1) -> PEREZ VERA | AT32: =SEARCH(" ",AS32) -> 6 | AU32: =MID(B32,AR32+2,90) -> MARLENE BETTY | AV32: =SEARCH(" ",AU32) -> 8
A33: 00045 | B33: ALARCON MONTALVAN, YAEL ASHLEY | C33: 73354131 | D33: 0 | E33: 0 | F33: 0 | G33: 0 | H33: 0 | I33: 0 | J33: 0 | K33: 0 | L33: 0 | M33: 0 | N33: 0 | O33: 0 | P33: 0 | Q33: 0 | R33: 0 | S33: 0 | T33: 0 | U33: 0 | V33: 0 | W33: 0 | X33: 0 | Y33: F | Z33: F | AA33: F | AB33: 0 | AC33: F | AD33: F | AE33: 0 | AF33: 0 | AG33: 0.015972222 | AH33: 0 | AJ33: 1 | AK33: =COUNTA(D33:AI33) -> 31 | AL33: 0.0069444444 | AM33: =COUNTIF(D33:AI33, ">00:10") -> 1 | AN33: =+AM33/AK33 -> 0.032258065 | AO33: =COUNTIF(D33:AI33,"F") -> 5 | AP33: =VLOOKUP(B33,Hoja3!$A$1:$B$14,2,0) -> CESADO | AQ33: =CONCATENATE(MID(AU33,1,AV33-1)," ",(MID(AS33,1,AT33-1))) -> YAEL ALARCON | AR33: =SEARCH(",",B33) -> 18 | AS33: =MID(B33,1,AR33-1) -> ALARCON MONTALVAN | AT33: =SEARCH(" ",AS33) -> 8 | AU33: =MID(B33,AR33+2,90) -> YAEL ASHLEY | AV33: =SEARCH(" ",AU33) -> 5
A34: 00001 | B34: CACERES CORDOVA, ROCIO SANDRA | C34: 48429690 | D34: 0 | E34: 0.015277778 | F34: 0.013194444 | G34: 0.025694444 | H34: 0.0097222222 | I34: 0.011805556 | J34: 0 | K34: 0 | L34: 0.0097222222 | M34: 0.013194444 | N34: 0.023611111 | O34: 0.0048611111 | P34: 0.019444444 | Q34: 0 | R34: 0 | S34: 0.01875 | T34: 0.014583333 | U34: 0.013194444 | V34: 0.021527778 | W34: 0.017361111 | X34: 0 | Y34: 0 | Z34: 0.0083333333 | AA34: 0.017361111 | AB34: 0.0069444444 | AC34: 0.019444444 | AD34: F | AE34: 0.00625 | AF34: 0 | AG34: 0.027777778 | AH34: 0.01875 | AJ34: 2 | AK34: =COUNTA(D34:AI34) -> 31 | AL34: 0.0069444444 | AM34: =COUNTIF(D34:AI34, ">00:10") -> 19 | AN34: =+AM34/AK34 -> 0.61290323 | AO34: =COUNTIF(D34:AI34,"F") -> 1 | AP34: ACTIVO | AQ34: =CONCATENATE(MID(AU34,1,AV34-1)," ",(MID(AS34,1,AT34-1))) -> ROCIO CACERES | AR34: =SEARCH(",",B34) -> 16 | AS34: =MID(B34,1,AR34-1) -> CACERES CORDOVA | AT34: =SEARCH(" ",AS34) -> 8 | AU34: =MID(B34,AR34+2,90) -> ROCIO SANDRA | AV34: =SEARCH(" ",AU34) -> 6
A35: 00003 | B35: LLANOS YAURI, LOURDES LUCIA | C35: 10602846 | D35: 0 | E35: 0.019444444 | F35: 0.010416667 | G35: 0.017361111 | H35: 0.025 | I35: 0.019444444 | J35: 0.020833333 | K35: 0 | L35: 0.033333333 | M35: 0.029861111 | N35: 0.025694444 | O35: 0.015277778 | P35: 0.022916667 | Q35: 0.030555556 | R35: 0 | S35: 0.0375 | T35: 0.022916667 | U35: 0.020833333 | V35: 0.027083333 | W35: 1:15 | X35: 0.01875 | Y35: 0 | Z35: 0 | AA35: 0.011111111 | AB35: 0.025694444 | AC35: 0.0013888889 | AD35: 0.011805556 | AE35: 0 | AF35: 0 | AG35: 0.016666667 | AH35: 0.022916667 | AJ35: 2 | AK35: =COUNTA(D35:AI35) -> 31 | AL35: 0.0069444444 | AM35: =COUNTIF(D35:AI35, ">00:10") -> 22 | AN35: =+AM35/AK35 -> 0.70967742 | AO35: =COUNTIF(D35:AI35,"F") -> 0 | AP35: ACTIVO | AQ35: =CONCATENATE(MID(AU35,1,AV35-1)," ",(MID(AS35,1,AT35-1))) -> LOURDES LLANOS | AR35: =SEARCH(",",B35) -> 13 | AS35: =MID(B35,1,AR35-1) -> LLANOS YAURI | AT35: =SEARCH(" ",AS35) -> 7 | AU35: =MID(B35,AR35+2,90) -> LOURDES LUCIA | AV35: =SEARCH(" ",AU35) -> 8
A36: 00004 | B36: TICLLA RAMOS, MARIELLA | C36: 72262268 | D36: 0 | E36: 0.027083333 | F36: 0 | G36: 0.010416667 | H36: 0 | I36: 0.01875 | J36: 0.0034722222 | K36: 0 | L36: 0.013194444 | M36: 0.023611111 | N36: 0.0083333333 | O36: 0.021527778 | P36: 0.018055556 | Q36: 0.0069444444 | R36: 0 | S36: 0.0097222222 | T36: 0.016666667 | U36: 0.0125 | V36: 0.014583333 | W36: 0.01875 | X36: 0.0076388889 | Y36: 0 | Z36: 0 | AA36: 0.0027777778 | AB36: 0.020138889 | AC36: 0.0013888889 | AD36: 0.0076388889 | AE36: 0.013194444 | AF36: 0 | AG36: 0.0069444444 | AH36: 0.016666667 | AJ36: 2 | AK36: =COUNTA(D36:AI36) -> 31 | AL36: 0.0069444444 | AM36: =COUNTIF(D36:AI36, ">00:10") -> 18 | AN36: =+AM36/AK36 -> 0.58064516 | AO36: =COUNTIF(D36:AI36,"F") -> 0 | AP36: ACTIVO | AQ36: =CONCATENATE(AU36," ",(MID(AS36,1,AT36-1))) -> MARIELLA TICLLA | AR36: =SEARCH(",",B36) -> 13 | AS36: =MID(B36,1,AR36-1) -> TICLLA RAMOS | AT36: =SEARCH(" ",AS36) -> 7 | AU36: =MID(B36,AR36+2,90) -> MARIELLA | AV36: =SEARCH(" ",AU36) -> #VALUE!
A37: 00006 | B37: PARIONA ROSAS, RICHARD | C37: 71001774 | D37: 0 | E37: 0 | F37: 0 | G37: 0.0076388889 | H37: 0.0083333333 | I37: 0.0020833333 | J37: 0.00625 | K37: 0 | L37: 0.0048611111 | M37: 0.0125 | N37: 0.0069444444 | O37: 0.028472222 | P37: 0.0034722222 | Q37: 0.0076388889 | R37: 0 | S37: 0.0013888889 | T37: 0.0125 | U37: 0.0055555556 | V37: 0.0034722222 | W37: 0 | X37: 0.0013888889 | Y37: 0 | Z37: 0.0020833333 | AA37: 0.0013888889 | AB37: 0.00069444444 | AC37: 0.00625 | AD37: 0 | AE37: 0.0375 | AF37: 0 | AG37: 0.0027777778 | AH37: 0.0013888889 | AJ37: 2 | AK37: =COUNTA(D37:AI37) -> 31 | AL37: 0.0069444444 | AM37: =COUNTIF(D37:AI37, ">00:10") -> 7 | AN37: =+AM37/AK37 -> 0.22580645 | AO37: =COUNTIF(D37:AI37,"F") -> 0 | AP37: ACTIVO | AQ37: =CONCATENATE(AU37," ",(MID(AS37,1,AT37-1))) -> RICHARD PARIONA | AR37: =SEARCH(",",B37) -> 14 | AS37: =MID(B37,1,AR37-1) -> PARIONA ROSAS | AT37: =SEARCH(" ",AS37) -> 8 | AU37: =MID(B37,AR37+2,90) -> RICHARD | AV37: =SEARCH(" ",AU37) -> #VALUE!
A38: 00007 | B38: GALINDO MERA, YAHAIRA LUZMILA | C38: 70655433 | D38: 0 | E38: 0.0125 | F38: 0.020138889 | G38: 0.016666667 | H38: 0.013888889 | I38: 0.0013888889 | J38: 0.0097222222 | K38: 0 | L38: 0 | M38: 0.0097222222 | N38: 0.014583333 | O38: 0.015277778 | P38: 0.018055556 | Q38: 0.0097222222 | R38: 0 | S38: 0 | T38: 0.015972222 | U38: 0.032638889 | V38: 0.040277778 | W38: 0.0048611111 | X38: 0.018055556 | Y38: 0 | Z38: 0.015277778 | AA38: 0.019444444 | AB38: 0.029861111 | AC38: 0.011805556 | AD38: 0.0076388889 | AE38: 0.0097222222 | AF38: 0 | AG38: 0.011805556 | AH38: 0.038888889 | AJ38: 2 | AK38: =COUNTA(D38:AI38) -> 31 | AL38: 0.0069444444 | AM38: =COUNTIF(D38:AI38, ">00:10") -> 22 | AN38: =+AM38/AK38 -> 0.70967742 | AO38: =COUNTIF(D38:AI38,"F") -> 0 | AP38: =VLOOKUP(B38,Hoja3!$A$1:$B$14,2,0) -> CESADO | AQ38: =CONCATENATE(MID(AU38,1,AV38-1)," ",(MID(AS38,1,AT38-1))) -> YAHAIRA GALINDO | AR38: =SEARCH(",",B38) -> 13 | AS38: =MID(B38,1,AR38-1) -> GALINDO MERA | AT38: =SEARCH(" ",AS38) -> 8 | AU38: =MID(B38,AR38+2,90) -> YAHAIRA LUZMILA | AV38: =SEARCH(" ",AU38) -> 8
A39: 00008 | B39: LLANOS ANTAURCO, STEPHEN BORIS | C39: 46183969 | D39: 0 | E39: 0 | F39: 0 | G39: 0.014583333 | H39: 0.00625 | I39: 0.010416667 | J39: 0.0034722222 | K39: 0 | L39: 0 | M39: 0.0076388889 | N39: 0.0055555556 | O39: 0 | P39: 0.00625 | Q39: 0.0097222222 | R39: 0 | S39: 5:06 | T39: 0 | U39: 0.0020833333 | V39: 0.0027777778 | W39: 0.0083333333 | X39: 0 | Y39: 0 | Z39: 0 | AA39: 0.015277778 | AB39: 0.0048611111 | AC39: 0 | AD39: 0 | AE39: 0 | AF39: 0 | AG39: 0 | AH39: 0.0013888889 | AJ39: 2 | AK39: =COUNTA(D39:AI39) -> 31 | AL39: 0.0069444444 | AM39: =COUNTIF(D39:AI39, ">00:10") -> 6 | AN39: =+AM39/AK39 -> 0.19354839 | AO39: =COUNTIF(D39:AI39,"F") -> 0 | AP39: ACTIVO | AQ39: =CONCATENATE(MID(AU39,1,AV39-1)," ",(MID(AS39,1,AT39-1))) -> STEPHEN LLANOS | AR39: =SEARCH(",",B39) -> 16 | AS39: =MID(B39,1,AR39-1) -> LLANOS ANTAURCO | AT39: =SEARCH(" ",AS39) -> 7 | AU39: =MID(B39,AR39+2,90) -> STEPHEN BORIS | AV39: =SEARCH(" ",AU39) -> 8
A40: 00010 | B40: CCAMA ARONI, LUZ MIRELLA | C40: 76575233 | D40: 0 | E40: 0.015972222 | F40: 0.01875 | G40: 0.019444444 | H40: 0.0125 | I40: 0.021527778 | J40: 0.0083333333 | K40: 0 | L40: 0.028472222 | M40: 0.0090277778 | N40: 0.020833333 | O40: 0.013194444 | P40: 0.019444444 | Q40: 0.022916667 | R40: 0 | S40: 0.0027777778 | T40: 0.022916667 | U40: 0.029166667 | V40: 0.021527778 | W40: 0.020833333 | X40: 0.029166667 | Y40: 0 | Z40: 0.020833333 | AA40: 0.013194444 | AB40: 0.025 | AC40: 0.016666667 | AD40: 0.016666667 | AE40: 0.020833333 | AF40: 0 | AG40: 0.020833333 | AH40: 0.027083333 | AJ40: 2 | AK40: =COUNTA(D40:AI40) -> 31 | AL40: 0.0069444444 | AM40: =COUNTIF(D40:AI40, ">00:10") -> 25 | AN40: =+AM40/AK40 -> 0.80645161 | AO40: =COUNTIF(D40:AI40,"F") -> 0 | AP40: ACTIVO | AQ40: =CONCATENATE(MID(AU40,1,AV40-1)," ",(MID(AS40,1,AT40-1))) -> LUZ CCAMA | AR40: =SEARCH(",",B40) -> 12 | AS40: =MID(B40,1,AR40-1) -> CCAMA ARONI | AT40: =SEARCH(" ",AS40) -> 6 | AU40: =MID(B40,AR40+2,90) -> LUZ MIRELLA | AV40: =SEARCH(" ",AU40) -> 4
...

Sheet Hoja3
A1: ALARCON MONTALVAN, YAEL ASHLEY | B1: CESADO
A2: ASIAN RAMIREZ, SILVIA LARITZA | B2: CESADO
A3: CCARI ASILLO, JHON MILTHON | B3: CESADO
A4: CHAVEZ GUILLEN, DIANA CAROLINA | B4: CESADO
A5: CLAROS NIETO, LITTA DANERY | B5: CESADO
A6: FELIX GARCIA, JEAN PIERRE | B6: CESADO
A7: GALINDO MERA, YAHAIRA LUZMILA | B7: CESADO
A8: GUEVARA ENRIQUEZ, ROGELIO | B8: CESADO
A9: LOPEZ CRUZ, JEFFERSON NORMAN | B9: CESADO
A10: MAYTA HUANCA, LUZ GABY | B10: CESADO
A11: PAREDES GUILLEN, ROCIO NOEMI | B11: CESADO
A12: PEREZ VERA, MARLENE BETTY | B12: CESADO
... A18: ALVAREZ MINAYA, BRIGHITTE SONIA | B18: CESADO

Sheet Hoja2
A1: ESTATUS | B1: ACTIVO
A3: Suma de Tard. > 00:10 | B3: Mes
A4: Etiquetas de fila | B4: 5 | C4: 6 | D4: 7 | E4: 8 | F4: Total general
A5: LUZ CCAMA | B5: 15 | C5: 22 | D5: 18 | E5: 13 | F5: 68
A6: MARIELLA TICLLA | B6: 19 | C6: 21 | D6: 13 | E6: 7 | F6: 60
A7: ROCIO CACERES | B7: 15 | C7: 22 | D7: 14 | E7: 9 | F7: 60
A8: KIMBERLLY AMES | B8: 15 | C8: 12 | D8: 13 | E8: 19 | F8: 59
A9: LILIANA ALVARADO | B9: 19 | C9: 25 | D9: 4 | E9: 11 | F9: 59
A10: LOURDES LLANOS | B10: 10 | C10: 17 | D10: 11 | E10: 16 | F10: 54
A11: RICHARD PARIONA | B11: 14 | C11: 24 | D11: 9 | E11: 4 | F11: 51
A12: IMANOL HANCCO | B12: 4 | C12: 9 | D12: 10 | E12: 8 | F12: 31
A13: GRECIA SANCHEZ | B13: 10 | C13: 15 | D13: 4 | E13: 0 | F13: 29
A14: OSCAR PARIAPAZA | B14: 6 | C14: 13 | D14: 0 | E14: 10 | F14: 29
A15: CARLOS LOPEZ | B15: 5 | C15: 9 | D15: 4 | E15: 8 | F15: 26
A16: STEPHEN LLANOS | B16: 7 | C16: 11 | D16: 4 | E16: 3 | F16: 25
... A27: Total general | B27: 165 | C27: 257 | D27: 131 | E27: 134 | F27: 687
